<mujoco model="base_surrounding">
  <compiler angle="radian" discardvisual="false" />
  <option collision="all" cone="elliptic" gravity="0 0 -9.81" impratio="3" solver="Newton" timestep="0.002" tolerance="1e-10" />
  <size nconmax="2000" njmax="2000" />
  <asset>
    <texture builtin="gradient" height="32" rgb1="0.26 0.58 0.51" rgb2="0.26 0.58 0.51" type="skybox" width="32" />
  </asset>
  <visual>
    <map zfar="1000" znear="0.001" />
    <scale actuatorwidth="0" />
  </visual>
  <worldbody>
    <light castshadow="true" cutoff="100" diffuse="1 1 1" dir="-0 0 -1.3" directional="true" exponent="1" pos="0 0 1.3" specular=".1 .1 .1" />
    <body name="ground" pos="0 0 -0.94">
      <geom name="ground:geom1" rgba="0.26 0.58 0.51 1" size="0 0 1" type="plane" />
    </body>

    <body name="box_0" pos="0 0 0.0" quat="1 0 0 0">
        <geom pos="0 0 0" size="0.05 0.05 0.01" rgba="1 0 0 1.0" type="box" mass="2.0" friction="0.3 0.001 0.0001" priority="1"/>
        <geom pos="0.05 0 0.0485" size="0.005 0.05 0.045" rgba="0 0 1 1.0" type="box" mass="0.001"/>
        <geom pos="0 0.05 0.0485" size="0.05 0.005 0.045" rgba="1 0 0 1.0" type="box" mass="0.001"/>
        <geom pos="-0.05 0 0.0485" size="0.005 0.05 0.045" rgba="1 0 0 1.0" type="box" mass="0.001"/>
        <geom pos="0 -0.05 0.0485" size="0.05 0.005 0.045" rgba="1 0 0 1.0" type="box" mass="0.001"/>
        <joint name="box_joint" type="free"/>
    </body>

    <body name="target_pos" pos="0 0 0">
    <!--body name="target_pos" pos="0.5 0.5 0.0"-->
      <site type="box" pos="0 0 0" rgba="0 1 0 0.3" size="0.05 0.05 0.01" />
      <site pos="0.05 0 0.0485" size="0.005 0.05 0.045" rgba="0 0 1 0.5" type="box"/>
      <site pos="0 0.05 0.0485" size="0.05 0.005 0.045" rgba="0 1 0 0.5" type="box"/>
      <site pos="-0.05 0 0.0485" size="0.005 0.05 0.045" rgba="0 1 0 0.5" type="box"/>
      <site pos="0 -0.05 0.0485" size="0.05 0.005 0.045" rgba="0 1 0 0.5" type="box"/>
    </body>

    <body name="replan_target_pos" pos="0 0 0">
    <!--body name="replan_target_pos" pos="0.5 0.5 1"-->
      <site type="box" pos="0 0 0" rgba="1 1 0 0.3" size="0.05 0.05 0.01" />
      <site pos="0.05 0 0.0485" size="0.005 0.05 0.045" rgba="0 0 1 0.5" type="box"/>
      <site pos="0 0.05 0.0485" size="0.05 0.005 0.045" rgba="1 1 0 0.5" type="box"/>
      <site pos="-0.05 0 0.0485" size="0.005 0.05 0.045" rgba="1 1 0 0.5" type="box"/>
      <site pos="0 -0.05 0.0485" size="0.05 0.005 0.045" rgba="1 1 0 0.5" type="box"/>
    </body>

    <body name="finger" pos="0 0 0">
    <!--body name="finger" pos="0.6 0.15 0.1"-->
     <geom type="cylinder" size="0.01 0.15" pos="0 0 0.075" mass="1.0"/>
     <site name="finger_tip" type="box" rgba="0 0 1 1." size="0.01 0.01 0.01" pos="0 0 0.2"/>
    <joint name="finger_x_joint" type="slide" pos="0 0 0" axis="1 0 0" limited="true" range="-0.33 0.03" damping="5"/>
    <joint name="finger_y_joint" type="slide" pos="0 0 0" axis="0 1 0" limited="true" range="-1 0.77" damping="5"/>
    </body>

  </worldbody>
  <actuator>
        <!-- Position controller for the slide joint along x-axis -->
        <position ctrllimited="false" forcelimited="true" forcerange="-10 10" joint="finger_x_joint" name="finger_x_actuator" kp="50"/>
        <position ctrllimited="false" forcelimited="true" forcerange="-10 10" joint="finger_y_joint" name="finger_y_actuator" kp="50"/>
        <!-- ... other actuators ... -->
    </actuator>
  <include file="kit_lab_surrounding.xml" />
</mujoco>
