<mujoco model="push_box">
    <worldbody>
        <body name="box_0" pos="0 0 0" quat="1 0 0 0">
        <geom conaffinity="8" pos="0 0 0.0016" size="0.064 0.064 0.003" rgba="1 0 0 1.0" type="box" mass="0.0308" friction="0.4296 0.001 0.0001" priority="1"/> <!-- bot -->
            <geom conaffinity="8" pos="0.056 0 0.0624" size="0.008 0.048 0.0624" rgba="0 0 1 1.0" type="box" mass="0.10714"/>
            <geom conaffinity="8" pos="0 0.056 0.0624" size="0.064 0.008 0.0624" rgba="1 0 0 1.0" type="box" mass="0.14286"/>
            <geom conaffinity="8" pos="-0.056 0 0.0624" size="0.008 0.048 0.0624" rgba="1 0 0 1.0" type="box" mass="0.10714"/>
            <geom conaffinity="8" pos="0 -0.056 0.0624" size="0.064 0.008 0.0624" rgba="1 0 0 1.0" type="box" mass="0.14286"/>
            <joint name="box_x_joint" type="slide" pos="0 0 0" axis="1 0 0" />
            <joint name="box_y_joint" type="slide" pos="0 0 0" axis="0 1 0" />
            <joint name="box_z_joint" type="slide" pos="0 0 0" axis="0 0 1" />
            <joint name="box_roll_joint" type="hinge" pos="0 0 0" axis="1 0 0" limited="true" range="-.15 .15"/>
            <joint name="box_pitch_joint" type="hinge" pos="0 0 0" axis="0 1 0" limited="true" range="-.15 .15"/>
            <joint name="box_rot_joint" type="hinge" pos="0 0 0" axis="0 0 1" />
        </body>
    </worldbody>
</mujoco>
